<?xml version="1.0"?>
<robot name="kuka_kr10r1100sixx_2" xmlns:xacro="http://wiki.ros.org/xacro">
  <xacro:include filename="$(find kuka_resources)/urdf/common_constants.xacro"/>
  <xacro:include filename="$(find kuka_resources)/urdf/common_materials.xacro"/>

  <xacro:macro name="kuka_kr10r1100sixx_2" params="prefix">
    <!-- links -->
    <link name="${prefix}base_link">
      <visual>
        <origin xyz="0 0 0" rpy="0 0 0"/>
        <geometry>
          <mesh filename="package://kuka_kr10_support/meshes/kr10r1100sixx_2/visual/base_link.stl" />
        </geometry>
        <xacro:material_kuka_black />
      </visual>
      <collision>
        <origin xyz="0 0 0" rpy="0 0 0"/>
        <geometry>
          <mesh filename="package://kuka_kr10_support/meshes/kr10r1100sixx_2/collision/base_link.stl" />
        </geometry>
      </collision>
    </link>

    <link name="${prefix}link_1">
      <visual>
        <origin xyz="0 0 0" rpy="0 0 0"/>
        <geometry>
          <mesh filename="package://kuka_kr10_support/meshes/kr10r1100sixx_2/visual/link_1.stl" />
        </geometry>
        <material
          name="">
          <color
            rgba="0.8 0.8 0.8 1" />
        </material>
      </visual>
      <collision>
        <origin xyz="0 0 0" rpy="0 0 0"/>
        <geometry>
          <mesh filename="package://kuka_kr10_support/meshes/kr10r1100sixx_2/collision/link_1.stl" />
        </geometry>
      </collision>
    </link>

    <link name="${prefix}link_2">
      <visual>
        <origin xyz="0 0 0" rpy="0 0 0"/>
        <geometry>
          <mesh filename="package://kuka_kr10_support/meshes/kr10r1100sixx_2/visual/link_2.stl"/>
        </geometry>
        <material
          name="">
          <color
            rgba="0.8 0.8 0.8 1" />
        </material>
      </visual>
      <collision>
        <origin xyz="0 0 0" rpy="0 0 0"/>
        <geometry>
          <mesh filename="package://kuka_kr10_support/meshes/kr10r1100sixx_2/collision/link_2.stl" />
        </geometry>
      </collision>
    </link>

    <link name="${prefix}link_3">
      <visual>
        <origin xyz="0 0 0" rpy="0 0 0"/>
        <geometry>
          <mesh filename="package://kuka_kr10_support/meshes/kr10r1100sixx_2/visual/link_3.stl" />
        </geometry>
        <material
          name="">
          <color
            rgba="0.8 0.8 0.8 1" />
        </material>
      </visual>
      <collision>
        <origin xyz="0 0 0" rpy="0 0 0"/>
        <geometry>
          <mesh filename="package://kuka_kr10_support/meshes/kr10r1100sixx_2/collision/link_3.stl" />
        </geometry>
      </collision>
    </link>

    <link name="${prefix}link_4">
      <visual>
        <origin xyz="0 0 0" rpy="0 0 0"/>
        <geometry>
          <mesh filename="package://kuka_kr10_support/meshes/kr10r1100sixx_2/visual/link_4.stl" />
        </geometry>
        <material
          name="">
          <color
            rgba="0.8 0.8 0.8 1" />
        </material>
      </visual>
      <collision>
        <origin xyz="0 0 0" rpy="0 0 0"/>
        <geometry>
          <mesh filename="package://kuka_kr10_support/meshes/kr10r1100sixx_2/collision/link_4.stl" />
        </geometry>
      </collision>
    </link>

    <link name="${prefix}link_5">
      <visual>
        <origin xyz="0 0 0" rpy="0 0 0"/>
        <geometry>
          <mesh filename="package://kuka_kr10_support/meshes/kr10r1100sixx_2/visual/link_5.stl" />
        </geometry>
        <material
          name="">
          <color
            rgba="0.8 0.8 0.8 1" />
        </material>
      </visual>
      <collision>
        <origin xyz="0 0 0" rpy="0 0 0"/>
        <geometry>
          <mesh filename="package://kuka_kr10_support/meshes/kr10r1100sixx_2/collision/link_5.stl" />
        </geometry>
      </collision>
    </link>

    <link name="${prefix}link_6">
      <visual>
        <origin xyz="0 0 0" rpy="0 0 0"/>
        <geometry>
          <mesh filename="package://kuka_kr10_support/meshes/kr10r1100sixx_2/visual/link_6.stl" />
        </geometry>
        <material
          name="">
          <color
            rgba="0.2 0.2 0.2 1" />
        </material>
      </visual>
      <collision>
        <origin xyz="0 0 0" rpy="0 0 0"/>
        <geometry>
          <mesh filename="package://kuka_kr10_support/meshes/kr10r1100sixx_2/collision/link_6.stl" />
        </geometry>
      </collision>
    </link>

    <!-- This frame corresponds to the $FLANGE coordinate system in KUKA KRC controllers -->
    <link name="${prefix}tool0"/>

    <!-- Following REP199, this frame shall be use to attach EEF or other equipment -->
    <!-- Add flange ROS-Industrial standard flange -->
    <link name="${prefix}flange" />

    <!-- Joints -->
    <joint name="${prefix}joint_a1" type="revolute">
      <origin xyz="0 0 0.2197" rpy="0 0 0"/>
      <parent link="${prefix}base_link"/>
      <child link="${prefix}link_1"/>
      <axis xyz="0 0 -1"/>
      <limit effort="0" lower="${radians(-170)}" upper="${radians(170)}" velocity="${radians(300)}"/>
    </joint>

    <joint name="${prefix}joint_a2" type="revolute">
      <origin xyz="0.025 0 0.1803" rpy="0 0 0"/>
      <parent link="${prefix}link_1"/>
      <child link="${prefix}link_2"/>
      <axis xyz="0 1 0"/>
      <limit effort="0" lower="${radians(-190)}" upper="${radians(45)}" velocity="${radians(225)}"/>
    </joint>

    <joint name="${prefix}joint_a3" type="revolute">
      <origin xyz="0.56 0 0" rpy="0 0 0"/>
      <parent link="${prefix}link_2"/>
      <child link="${prefix}link_3"/>
      <axis xyz="0 1 0"/>
      <limit effort="0" lower="${radians(-120)}" upper="${radians(156)}" velocity="${radians(225)}"/>
    </joint>

    <joint name="${prefix}joint_a4" type="revolute">
      <origin xyz="0.205 0.0045 0.025" rpy="0 0 0"/>
      <parent link="${prefix}link_3"/>
      <child link="${prefix}link_4"/>
      <axis xyz="-1 0 0"/>
      <limit effort="0" lower="${radians(-185)}" upper="${radians(185)}" velocity="${radians(381)}"/>
    </joint>

    <joint name="${prefix}joint_a5" type="revolute">
      <origin xyz="0.31 0 0" rpy="0 0 0"/>
      <parent link="${prefix}link_4"/>
      <child link="${prefix}link_5"/>
      <axis xyz="0 1 0"/>
      <limit effort="0" lower="${radians(-120)}" upper="${radians(120)}" velocity="${radians(311)}"/>
    </joint>

    <joint name="${prefix}joint_a6" type="revolute">
      <origin xyz="0.067 0.00325 0" rpy="0 0 0"/>
      <parent link="${prefix}link_5"/>
      <child link="${prefix}link_6"/>
      <axis xyz="-11 0 0"/>
      <limit effort="0" lower="${radians(-350)}" upper="${radians(350)}" velocity="${radians(492)}"/>
    </joint>

    <joint name="${prefix}link_6-tool0" type="fixed">
      <origin xyz="0.023 0 0" rpy="0 1.57079632679 0"/>
      <parent link="${prefix}link_6"/>
      <child link="${prefix}tool0"/>
    </joint>

    <joint name="${prefix}link_6-flange" type="fixed">
      <origin xyz="0.023 0 0" rpy="0 1.57079632679 0"/>
      <parent link="${prefix}link_6"/>
      <child link="${prefix}flange"/>
    </joint>

    <!-- ROS base_link to KUKA $ROBROOT coordinate system transform -->
    <!-- <link name="${prefix}base" />
    <joint name="${prefix}base_link-base" type="fixed">
      <origin xyz="0 0 0" rpy="0 0 0"/>
      <parent link="${prefix}base_link"/>
      <child link="${prefix}base"/>
    </joint> -->

    <!-- This frame corresponds to the $TOOL coordinate system in KUKA KRC controllers -->
    <!-- <link name="${prefix}tool0" />
    <joint name="${prefix}flange-tool0" type="fixed">
      <parent link="${prefix}flange"/>
      <child link="${prefix}tool0"/>
      <origin xyz="0 0 0" rpy="0 ${radians(90)} 0"/>
    </joint> -->
  </xacro:macro>
</robot>
