<?xml version="1.0"?>
<robot xmlns:xacro="http://wiki.ros.org/xacro">
  <xacro:include filename="$(find kuka_resources)/urdf/common_constants.xacro"/>
  <xacro:include filename="$(find kuka_resources)/urdf/common_materials.xacro"/>

  <xacro:macro name="kuka_kr16r2010_2" params="prefix">
    <!-- LINKS -->
    <!-- base link -->
    <link name="${prefix}base_link">
      <inertial>
        <origin xyz="0 0 0" rpy="0 0 0"/>
        <mass value="2"/>
        <inertia ixx="0.01" ixy="0" ixz="0" iyy="0.01" iyz="0" izz="0.01" />
      </inertial>
      <visual>
        <origin xyz="0 0 0" rpy="0 0 0"/>
        <geometry>
          <mesh filename="package://kuka_kr16_support/meshes/kr16r2010_2/visual/base_link.stl" />
        </geometry>
        <xacro:material_kuka_black />
      </visual>
      <collision>
        <origin xyz="0 0 0" rpy="0 0 0"/>
        <geometry>
          <mesh filename="package://kuka_kr16_support/meshes/kr16r2010_2/collision/base_link.stl" />
        </geometry>
      </collision>
    </link>
    <!-- link 1 (A1) -->
    <link name="${prefix}link_1">
      <inertial>
        <origin xyz="0 0 0" rpy="0 0 0"/>
        <mass value="2"/>
        <inertia ixx="0.01" ixy="0" ixz="0" iyy="0.01" iyz="0" izz="0.01" />
      </inertial>
      <visual>
        <origin xyz="0 0 0" rpy="0 0 0"/>
        <geometry>
          <mesh filename="package://kuka_kr16_support/meshes/kr16r2010_2/visual/link_1.stl" />
        </geometry>
        <xacro:material_kuka_orange />
      </visual>
      <collision>
        <origin xyz="0 0 0" rpy="0 0 0"/>
        <geometry>
          <mesh filename="package://kuka_kr16_support/meshes/kr16r2010_2/collision/link_1.stl" />
        </geometry>
      </collision>
    </link>
    <!-- link 2 -->
    <link name="${prefix}link_2">
      <inertial>
        <origin xyz="0 0 0" rpy="0 0 0"/>
        <mass value="2"/>
        <inertia ixx="0.01" ixy="0" ixz="0" iyy="0.01" iyz="0" izz="0.01" />
      </inertial>
      <visual>
        <origin xyz="0 0 0" rpy="0 0 0"/>
        <geometry>
          <mesh filename="package://kuka_kr16_support/meshes/kr16r2010_2/visual/link_2.stl"/>
        </geometry>
        <xacro:material_kuka_orange />
      </visual>
      <collision>
        <origin xyz="0 0 0" rpy="0 0 0"/>
        <geometry>
          <mesh filename="package://kuka_kr16_support/meshes/kr16r2010_2/collision/link_2.stl" />
        </geometry>
      </collision>
    </link>
    <!-- link 3 -->
    <link name="${prefix}link_3">
      <inertial>
        <origin xyz="0 0 0" rpy="0 0 0"/>
        <mass value="2"/>
        <inertia ixx="0.01" ixy="0" ixz="0" iyy="0.01" iyz="0" izz="0.01" />
      </inertial>
      <visual>
        <origin xyz="0 0 0" rpy="0 0 0"/>
        <geometry>
          <mesh filename="package://kuka_kr16_support/meshes/kr16r2010_2/visual/link_3.stl" />
        </geometry>
        <xacro:material_kuka_orange />
      </visual>
      <collision>
        <origin xyz="0 0 0" rpy="0 0 0"/>
        <geometry>
          <mesh filename="package://kuka_kr16_support/meshes/kr16r2010_2/collision/link_3.stl" />
        </geometry>
      </collision>
    </link>
    <!-- link 4 -->
    <link name="${prefix}link_4">
      <inertial>
        <origin xyz="0 0 0" rpy="0 0 0"/>
        <mass value="2"/>
        <inertia ixx="0.01" ixy="0" ixz="0" iyy="0.01" iyz="0" izz="0.01" />
      </inertial>
      <visual>
        <origin xyz="0 0 0" rpy="0 0 0"/>
        <geometry>
          <mesh filename="package://kuka_kr16_support/meshes/kr16r2010_2/visual/link_4.stl" />
        </geometry>
        <xacro:material_kuka_orange />
      </visual>
      <collision>
        <origin xyz="0 0 0" rpy="0 0 0"/>
        <geometry>
          <mesh filename="package://kuka_kr16_support/meshes/kr16r2010_2/collision/link_4.stl" />
        </geometry>
      </collision>
    </link>
    <!-- link 5 -->
    <link name="${prefix}link_5">
      <inertial>
        <origin xyz="0 0 0" rpy="0 0 0"/>
        <mass value="2"/>
        <inertia ixx="0.01" ixy="0" ixz="0" iyy="0.01" iyz="0" izz="0.01" />
      </inertial>
      <visual>
        <origin xyz="0 0 0" rpy="0 0 0"/>
        <geometry>
          <mesh filename="package://kuka_kr16_support/meshes/kr16r2010_2/visual/link_5.stl" />
        </geometry>
        <xacro:material_kuka_orange />
      </visual>
      <collision>
        <origin xyz="0 0 0" rpy="0 0 0"/>
        <geometry>
          <mesh filename="package://kuka_kr16_support/meshes/kr16r2010_2/collision/link_5.stl" />
        </geometry>
      </collision>
    </link>
    <!-- link 6 -->
    <link name="${prefix}link_6">
      <inertial>
        <origin xyz="0 0 0" rpy="0 0 0"/>
        <mass value="2"/>
        <inertia ixx="0.01" ixy="0" ixz="0" iyy="0.01" iyz="0" izz="0.01" />
      </inertial>
      <visual>
        <origin xyz="0 0 0" rpy="0 0 0"/>
        <geometry>
          <mesh filename="package://kuka_kr16_support/meshes/kr16r2010_2/visual/link_6.stl" />
        </geometry>
        <xacro:material_kuka_pedestal />
      </visual>
      <collision>
        <origin xyz="0 0 0" rpy="0 0 0"/>
        <geometry>
          <mesh filename="package://kuka_kr16_support/meshes/kr16r2010_2/collision/link_6.stl" />
        </geometry>
      </collision>
    </link>
    <!-- tool 0 -->
    <!-- Following REP199, this frame shall be use to attach EEF or other equipment -->
    <link name="${prefix}flange" />
    <!-- END LINKS -->

    <!-- JOINTS -->
    <!-- joint 1 (A1) -->
    <joint name="${prefix}joint_a1" type="revolute">
      <origin xyz="0.02513108361 0.00023848565 0.27446903331" rpy="0 0 0"/>
      <parent link="${prefix}base_link"/>
      <child link="${prefix}link_1"/>
      <axis xyz="0 0 -1"/>
      <limit effort="0" lower="${radians(-185)}" upper="${radians(185)}" velocity="${radians(200)}"/>
    </joint>
    <!-- joint 2 (A2) -->
    <joint name="${prefix}joint_a2" type="revolute">
      <origin xyz="0.160 -0.09480000000 0.24553096669" rpy="${radians(90)} ${radians(90)} ${radians(0)}"/>
      <parent link="${prefix}link_1"/>
      <child link="${prefix}link_2"/>
      <axis xyz="0 0 -1"/>
      <limit effort="0" lower="${radians(-185)}" upper="${radians(65)}" velocity="${radians(175)}"/>
    </joint>
    <!-- joint 3 (A3) -->
    <joint name="${prefix}joint_a3" type="revolute">
      <origin xyz="0.0 0.980 0.023" rpy="0 0 ${radians(90)}"/>
      <parent link="${prefix}link_2"/>
      <child link="${prefix}link_3"/>
      <axis xyz="0 0 -1"/>
      <limit effort="0" lower="${radians(-138)}" upper="${radians(175)}" velocity="${radians(190)}"/>
    </joint>
    <!-- joint 4 (A4) -->
    <joint name="${prefix}joint_a4" type="revolute">
      <origin xyz="0.3 0.15 -0.1151" rpy="${radians(90)} ${radians(180)} ${radians(90)}"/>
      <parent link="${prefix}link_3"/>
      <child link="${prefix}link_4"/>
      <axis xyz="0 0 -1"/>
      <limit effort="0" lower="${radians(-350)}" upper="${radians(350)}" velocity="${radians(430)}"/>
    </joint>
    <!-- joint 5 (A5) -->
    <joint name="${prefix}joint_a5" type="revolute">
      <origin xyz="0 0.0923 0.56000000307" rpy="${radians(90)} ${radians(-90)} ${radians(0)}"/>
      <parent link="${prefix}link_4"/>
      <child link="${prefix}link_5"/>
      <axis xyz="0 0 -1"/>
      <limit effort="0" lower="${radians(-130)}" upper="${radians(130)}" velocity="${radians(430)}"/>
    </joint>
    <!-- joint 6 (A6) -->
    <joint name="${prefix}joint_a6" type="revolute">
      <origin xyz="0.139 0.0 0.0923" rpy="${radians(90)} ${radians(180)} ${radians(90)}"/>
      <parent link="${prefix}link_5"/>
      <child link="${prefix}link_6"/>
      <axis xyz="0 0 -1"/>
      <limit effort="0" lower="${radians(-350)}" upper="${radians(350)}" velocity="${radians(630)}"/>
    </joint>
    <!-- tool frame - fixed frame -->
    <joint name="${prefix}joint_a6-flange" type="fixed">
      <parent link="${prefix}link_6"/>
      <child link="${prefix}flange"/>
      <origin xyz="0.0 0 0.014" rpy="0 0 0"/>
    </joint>
    <!-- END JOINTS -->

    <!-- ROS base_link to KUKA $ROBROOT coordinate system transform -->
    <link name="${prefix}base" />
    <joint name="${prefix}base_link-base" type="fixed">
      <origin xyz="0 0 0" rpy="0 0 0"/>
      <parent link="${prefix}base_link"/>
      <child link="${prefix}base"/>
    </joint>

    <!-- This frame corresponds to the $TOOL coordinate system in KUKA KRC controllers -->
    <link name="${prefix}tool0" />
    <joint name="${prefix}flange-tool0" type="fixed">
      <parent link="${prefix}flange"/>
      <child link="${prefix}tool0"/>
      <origin xyz="0 0 0" rpy="0 ${radians(90)} 0"/>
    </joint>

  </xacro:macro>
</robot>
