<?xml version='1.0' encoding='utf-8'?>
<robot xmlns:xacro="http://www.ros.org/wiki/xacro">
    <VERSION value="1.0.0" />
    <xacro:arg default="" name="prefix" />
    <xacro:arg default="" name="urdf_package_name" />
    <xacro:macro name="kuka_kr16r1610_2" params="prefix urdf_package_name">
      <xacro:include filename="kr16r1610_2_params.xacro" />
      <!--Default materials-->
      <material name="orange">
        <color rgba="${246/255} ${120/255} ${40/255} 1" />
      </material>
      <material name="black">
        <color rgba="0 0 0 1" />
      </material>
      <!--ROS base_link to KUKA $ROBROOT coordinate system transform-->
      <link name="${prefix}base" />
      <!--This frame corresponds to the $TOOL coordinate system in KUKA KRC controllers-->
      <link name="${prefix}flange" />
      <joint name="${prefix}joint_flange" type="fixed">
        <origin rpy="0 ${pi} 0" xyz="0 0 0" />
        <parent link="${prefix}link_6" />
        <child link="${prefix}flange" />
      </joint>
      <link name="${prefix}tool0" />
      <joint name="${prefix}joint_tool0" type="fixed">
        <origin rpy="0 0 0" xyz="0 0 0" />
        <parent link="${prefix}flange" />
        <child link="${prefix}tool0" />
      </joint>
      <!--KR16R1610_2 link-->
      <link name="${prefix}base_link">
        <visual>
          <origin rpy="0 0 0" xyz="0 0 0" />
          <geometry>
            <mesh filename="package://${urdf_package_name}/urdf/robots/kr16r1610_2/meshes/visual/base_link.dae" />
          </geometry>
          <material name="orange" />
        </visual>
        <collision>
          <origin rpy="0 0 0" xyz="0 0 0" />
          <geometry>
            <mesh filename="package://${urdf_package_name}/urdf/robots/kr16r1610_2/meshes/collision/base_link.stl" />
          </geometry>
          <material name="orange" />
        </collision>
      </link>
      <!--KR16R1610_2 joint-->
      <joint name="${prefix}joint_base_link-base" type="fixed">
        <origin rpy="${base_link_orientation_r} ${base_link_orientation_p} ${base_link_orientation_y}" xyz="${base_link_origin_x} ${base_link_origin_y} ${base_link_origin_z}" />
        <parent link="${prefix}base" />
        <child link="${prefix}base_link" />
      </joint>
      <!--A1 link-->
      <link name="${prefix}link_1">
        <inertial>
          <origin rpy="0 0 0" xyz="${link_1_cm_x} ${link_1_cm_y} ${link_1_cm_z}" />
          <mass value="${link_1_mass}" />
          <inertia ixx="${link_1_ixx}" ixy="0" ixz="0" iyy="${link_1_iyy}" iyz="0" izz="${link_1_izz}" />
        </inertial>
        <visual>
          <origin rpy="0 0 0" xyz="0 0 0" />
          <geometry>
            <mesh filename="package://${urdf_package_name}/urdf/robots/kr16r1610_2/meshes/visual/link_1.dae" />
          </geometry>
          <material name="orange" />
        </visual>
        <collision>
          <origin rpy="0 0 0" xyz="0 0 0" />
          <geometry>
            <mesh filename="package://${urdf_package_name}/urdf/robots/kr16r1610_2/meshes/collision/link_1.stl" />
          </geometry>
          <material name="orange" />
        </collision>
      </link>
      <!--A1 joint-->
      <joint name="${prefix}joint_1" type="revolute">
        <limit effort="${joint_1_trq}" lower="${radians(joint_1_lower_lim)}" upper="${radians(joint_1_upper_lim)}" velocity="${radians(joint_1_spd)}" />
        <axis xyz="0 0 -1" />
        <origin rpy="${link_1_orientation_r} ${link_1_orientation_p} ${link_1_orientation_y}" xyz="${link_1_origin_x} ${link_1_origin_y} ${link_1_origin_z}" />
        <parent link="${prefix}base_link" />
        <child link="${prefix}link_1" />
      </joint>
      <!--A2 link-->
      <link name="${prefix}link_2">
        <inertial>
          <origin rpy="0 0 0" xyz="${link_2_cm_x} ${link_2_cm_y} ${link_2_cm_z}" />
          <mass value="${link_2_mass}" />
          <inertia ixx="${link_2_ixx}" ixy="0" ixz="0" iyy="${link_2_iyy}" iyz="0" izz="${link_2_izz}" />
        </inertial>
        <visual>
          <origin rpy="0 0 0" xyz="0 0 0" />
          <geometry>
            <mesh filename="package://${urdf_package_name}/urdf/robots/kr16r1610_2/meshes/visual/link_2.dae" />
          </geometry>
          <material name="orange" />
        </visual>
        <collision>
          <origin rpy="0 0 0" xyz="0 0 0" />
          <geometry>
            <mesh filename="package://${urdf_package_name}/urdf/robots/kr16r1610_2/meshes/collision/link_2.stl" />
          </geometry>
          <material name="orange" />
        </collision>
      </link>
      <!--A2 joint-->
      <joint name="${prefix}joint_2" type="revolute">
        <limit effort="${joint_2_trq}" lower="${radians(joint_2_lower_lim)}" upper="${radians(joint_2_upper_lim)}" velocity="${radians(joint_2_spd)}" />
        <axis xyz="0 1 0" />
        <origin rpy="${link_2_orientation_r} ${link_2_orientation_p} ${link_2_orientation_y}" xyz="${link_2_origin_x} ${link_2_origin_y} ${link_2_origin_z}" />
        <parent link="${prefix}link_1" />
        <child link="${prefix}link_2" />
      </joint>
      <!--A3 link-->
      <link name="${prefix}link_3">
        <inertial>
          <origin rpy="0 0 0" xyz="${link_3_cm_x} ${link_3_cm_y} ${link_3_cm_z}" />
          <mass value="${link_3_mass}" />
          <inertia ixx="${link_3_ixx}" ixy="0" ixz="0" iyy="${link_3_iyy}" iyz="0" izz="${link_3_izz}" />
        </inertial>
        <visual>
          <origin rpy="0 0 0" xyz="0 0 0" />
          <geometry>
            <mesh filename="package://${urdf_package_name}/urdf/robots/kr16r1610_2/meshes/visual/link_3.dae" />
          </geometry>
          <material name="orange" />
        </visual>
        <collision>
          <origin rpy="0 0 0" xyz="0 0 0" />
          <geometry>
            <mesh filename="package://${urdf_package_name}/urdf/robots/kr16r1610_2/meshes/collision/link_3.stl" />
          </geometry>
          <material name="orange" />
        </collision>
      </link>
      <!--A3 joint-->
      <joint name="${prefix}joint_3" type="revolute">
        <limit effort="${joint_3_trq}" lower="${radians(joint_3_lower_lim)}" upper="${radians(joint_3_upper_lim)}" velocity="${radians(joint_3_spd)}" />
        <axis xyz="0 1 0" />
        <origin rpy="${link_3_orientation_r} ${link_3_orientation_p} ${link_3_orientation_y}" xyz="${link_3_origin_x} ${link_3_origin_y} ${link_3_origin_z}" />
        <parent link="${prefix}link_2" />
        <child link="${prefix}link_3" />
      </joint>
      <!--A4 link-->
      <link name="${prefix}link_4">
        <inertial>
          <origin rpy="0 0 0" xyz="${link_4_cm_x} ${link_4_cm_y} ${link_4_cm_z}" />
          <mass value="${link_4_mass}" />
          <inertia ixx="${link_4_ixx}" ixy="0" ixz="0" iyy="${link_4_iyy}" iyz="0" izz="${link_4_izz}" />
        </inertial>
        <visual>
          <origin rpy="0 0 0" xyz="0 0 0" />
          <geometry>
            <mesh filename="package://${urdf_package_name}/urdf/robots/kr16r1610_2/meshes/visual/link_4.dae" />
          </geometry>
          <material name="orange" />
        </visual>
        <collision>
          <origin rpy="0 0 0" xyz="0 0 0" />
          <geometry>
            <mesh filename="package://${urdf_package_name}/urdf/robots/kr16r1610_2/meshes/collision/link_4.stl" />
          </geometry>
          <material name="orange" />
        </collision>
      </link>
      <!--A4 joint-->
      <joint name="${prefix}joint_4" type="revolute">
        <limit effort="${joint_4_trq}" lower="${radians(joint_4_lower_lim)}" upper="${radians(joint_4_upper_lim)}" velocity="${radians(joint_4_spd)}" />
        <axis xyz="0 0 -1" />
        <origin rpy="${link_4_orientation_r} ${link_4_orientation_p} ${link_4_orientation_y}" xyz="${link_4_origin_x} ${link_4_origin_y} ${link_4_origin_z}" />
        <parent link="${prefix}link_3" />
        <child link="${prefix}link_4" />
      </joint>
      <!--A5 link-->
      <link name="${prefix}link_5">
        <inertial>
          <origin rpy="0 0 0" xyz="${link_5_cm_x} ${link_5_cm_y} ${link_5_cm_z}" />
          <mass value="${link_5_mass}" />
          <inertia ixx="${link_5_ixx}" ixy="0" ixz="0" iyy="${link_5_iyy}" iyz="0" izz="${link_5_izz}" />
        </inertial>
        <visual>
          <origin rpy="0 0 0" xyz="0 0 0" />
          <geometry>
            <mesh filename="package://${urdf_package_name}/urdf/robots/kr16r1610_2/meshes/visual/link_5.dae" />
          </geometry>
          <material name="orange" />
        </visual>
        <collision>
          <origin rpy="0 0 0" xyz="0 0 0" />
          <geometry>
            <mesh filename="package://${urdf_package_name}/urdf/robots/kr16r1610_2/meshes/collision/link_5.stl" />
          </geometry>
          <material name="orange" />
        </collision>
      </link>
      <!--A5 joint-->
      <joint name="${prefix}joint_5" type="revolute">
        <limit effort="${joint_5_trq}" lower="${radians(joint_5_lower_lim)}" upper="${radians(joint_5_upper_lim)}" velocity="${radians(joint_5_spd)}" />
        <axis xyz="0 0 1" />
        <origin rpy="${link_5_orientation_r} ${link_5_orientation_p} ${link_5_orientation_y}" xyz="${link_5_origin_x} ${link_5_origin_y} ${link_5_origin_z}" />
        <parent link="${prefix}link_4" />
        <child link="${prefix}link_5" />
      </joint>
      <!--A6 link-->
      <link name="${prefix}link_6">
        <inertial>
          <origin rpy="0 0 0" xyz="${link_6_cm_x} ${link_6_cm_y} ${link_6_cm_z}" />
          <mass value="${link_6_mass}" />
          <inertia ixx="${link_6_ixx}" ixy="0" ixz="0" iyy="${link_6_iyy}" iyz="0" izz="${link_6_izz}" />
        </inertial>
        <visual>
          <origin rpy="0 0 0" xyz="0 0 0" />
          <geometry>
            <mesh filename="package://${urdf_package_name}/urdf/robots/kr16r1610_2/meshes/visual/link_6.dae" />
          </geometry>
          <material name="orange" />
        </visual>
        <collision>
          <origin rpy="0 0 0" xyz="0 0 0" />
          <geometry>
            <mesh filename="package://${urdf_package_name}/urdf/robots/kr16r1610_2/meshes/collision/link_6.stl" />
          </geometry>
          <material name="orange" />
        </collision>
      </link>
      <!--A6 joint-->
      <joint name="${prefix}joint_6" type="revolute">
        <limit effort="${joint_6_trq}" lower="${radians(joint_6_lower_lim)}" upper="${radians(joint_6_upper_lim)}" velocity="${radians(joint_6_spd)}" />
        <axis xyz="0 0 -1" />
        <origin rpy="${link_6_orientation_r} ${link_6_orientation_p} ${link_6_orientation_y}" xyz="${link_6_origin_x} ${link_6_origin_y} ${link_6_origin_z}" />
        <parent link="${prefix}link_5" />
        <child link="${prefix}link_6" />
      </joint>
    </xacro:macro>
  </robot>
  